[INFO][0][<module>] Linux derecho3 5.14.21-150400.24.18-default #1 SMP PREEMPT_DYNAMIC Thu Aug 4 14:17:48 UTC 2022 (e9f7bfc) x86_64 x86_64
[INFO][0][<module>] /glade/u/home/rfisher/.local/lib/python3.9/site-packages/ILAMB (2.7)
[INFO][0][<module>] /glade/u/apps/opt/conda/envs/npl-2023a/lib/python3.9/site-packages/numpy (1.23.5)
[INFO][0][<module>] /glade/u/apps/opt/conda/envs/npl-2023a/lib/python3.9/site-packages/matplotlib (3.6.3)
[INFO][0][<module>] /glade/u/apps/opt/conda/envs/npl-2023a/lib/python3.9/site-packages/netCDF4 (1.6.2)
[INFO][0][<module>] /glade/u/apps/opt/conda/envs/npl-2023a/lib/python3.9/site-packages/cf_units (3.1.1)
[INFO][0][<module>] /glade/u/home/rfisher/.local/lib/python3.9/site-packages/sympy (1.12)
[INFO][0][<module>] /glade/u/apps/opt/conda/envs/npl-2023a/lib/python3.9/site-packages/mpi4py (3.1.4)
[INFO][0][<module>] 2024-06-10 04:09:33.014108
[INFO][0][MakeComparable][Biomass/NBCD2000][4x5_out_of_the_box_ann] Spatial data was clipped from the reference:  before: [  1 360 720] after: [  1 360 711]
[INFO][0][AnalysisMeanStateSpace][biomass] Bias scored using Collier2018
[INFO][0][confront][Biomass/NBCD2000][4x5_out_of_the_box_ann] Success
[DEBUG][0][WorkConfront][Biomass/Thurner][4x5_out_of_the_box_ann]
ValueError: Error from parse_expr with transformed code: 'FATES_FRACTION *FATES_VEGC '

The above exception was the direct cause of the following exception:

Traceback (most recent call last):
  File "/glade/u/home/rfisher/.local/bin/ilamb-run", line 561, in WorkConfront
    c.confront(m)
  File "/glade/u/home/rfisher/.local/lib/python3.9/site-packages/ILAMB/Confrontation.py", line 431, in confront
    obs, mod = self.stageData(m)
  File "/glade/u/home/rfisher/.local/lib/python3.9/site-packages/ILAMB/Confrontation.py", line 369, in stageData
    mod = m.extractTimeSeries(
  File "/glade/u/home/rfisher/.local/lib/python3.9/site-packages/ILAMB/ModelResult.py", line 413, in extractTimeSeries
    v = self.derivedVariable(
  File "/glade/u/home/rfisher/.local/lib/python3.9/site-packages/ILAMB/ModelResult.py", line 553, in derivedVariable
    result, unit = il.SympifyWithArgsUnits(expression, args, units)
  File "/glade/u/home/rfisher/.local/lib/python3.9/site-packages/ILAMB/ilamblib.py", line 632, in SympifyWithArgsUnits
    return sympify(str(expression), locals=args), units[ekey]
  File "/glade/u/home/rfisher/.local/lib/python3.9/site-packages/sympy/core/sympify.py", line 495, in sympify
    expr = parse_expr(a, local_dict=locals, transformations=transformations, evaluate=evaluate)
  File "/glade/u/home/rfisher/.local/lib/python3.9/site-packages/sympy/parsing/sympy_parser.py", line 1087, in parse_expr
    raise e from ValueError(f"Error from parse_expr with transformed code: {code!r}")
  File "/glade/u/home/rfisher/.local/lib/python3.9/site-packages/sympy/parsing/sympy_parser.py", line 1078, in parse_expr
    rv = eval_expr(code, local_dict, global_dict)
  File "/glade/u/home/rfisher/.local/lib/python3.9/site-packages/sympy/parsing/sympy_parser.py", line 906, in eval_expr
    expr = eval(
  File "<string>", line 1, in <module>
FloatingPointError: overflow encountered in multiply

[DEBUG][0][extractTimeSeries][4x5_out_of_the_box_ann] Could not find [FATES_VEGC] in the model results
[DEBUG][0][WorkConfront][Biomass/ESACCI][4x5_out_of_the_box_ann]
Traceback (most recent call last):
  File "/glade/u/home/rfisher/.local/bin/ilamb-run", line 561, in WorkConfront
    c.confront(m)
  File "/glade/u/home/rfisher/.local/lib/python3.9/site-packages/ILAMB/Confrontation.py", line 431, in confront
    obs, mod = self.stageData(m)
  File "/glade/u/home/rfisher/.local/lib/python3.9/site-packages/ILAMB/Confrontation.py", line 369, in stageData
    mod = m.extractTimeSeries(
  File "/glade/u/home/rfisher/.local/lib/python3.9/site-packages/ILAMB/ModelResult.py", line 413, in extractTimeSeries
    v = self.derivedVariable(
  File "/glade/u/home/rfisher/.local/lib/python3.9/site-packages/ILAMB/ModelResult.py", line 499, in derivedVariable
    Vs[arg] = self.extractTimeSeries(
  File "/glade/u/home/rfisher/.local/lib/python3.9/site-packages/ILAMB/ModelResult.py", line 437, in extractTimeSeries
    raise il.VarNotInModel()
ILAMB.ilamblib.VarNotInModel: VarNotInModel

[DEBUG][0][WorkConfront][GrossPrimaryProductivity/FLUXNET2015][4x5_out_of_the_box_ann]
ValueError: Error from parse_expr with transformed code: 'FATES_FRACTION *FATES_GPP '

The above exception was the direct cause of the following exception:

Traceback (most recent call last):
  File "/glade/u/home/rfisher/.local/bin/ilamb-run", line 561, in WorkConfront
    c.confront(m)
  File "/glade/u/home/rfisher/.local/lib/python3.9/site-packages/ILAMB/Confrontation.py", line 431, in confront
    obs, mod = self.stageData(m)
  File "/glade/u/home/rfisher/.local/lib/python3.9/site-packages/ILAMB/Confrontation.py", line 369, in stageData
    mod = m.extractTimeSeries(
  File "/glade/u/home/rfisher/.local/lib/python3.9/site-packages/ILAMB/ModelResult.py", line 413, in extractTimeSeries
    v = self.derivedVariable(
  File "/glade/u/home/rfisher/.local/lib/python3.9/site-packages/ILAMB/ModelResult.py", line 553, in derivedVariable
    result, unit = il.SympifyWithArgsUnits(expression, args, units)
  File "/glade/u/home/rfisher/.local/lib/python3.9/site-packages/ILAMB/ilamblib.py", line 632, in SympifyWithArgsUnits
    return sympify(str(expression), locals=args), units[ekey]
  File "/glade/u/home/rfisher/.local/lib/python3.9/site-packages/sympy/core/sympify.py", line 495, in sympify
    expr = parse_expr(a, local_dict=locals, transformations=transformations, evaluate=evaluate)
  File "/glade/u/home/rfisher/.local/lib/python3.9/site-packages/sympy/parsing/sympy_parser.py", line 1087, in parse_expr
    raise e from ValueError(f"Error from parse_expr with transformed code: {code!r}")
  File "/glade/u/home/rfisher/.local/lib/python3.9/site-packages/sympy/parsing/sympy_parser.py", line 1078, in parse_expr
    rv = eval_expr(code, local_dict, global_dict)
  File "/glade/u/home/rfisher/.local/lib/python3.9/site-packages/sympy/parsing/sympy_parser.py", line 906, in eval_expr
    expr = eval(
  File "<string>", line 1, in <module>
FloatingPointError: overflow encountered in multiply

[DEBUG][0][WorkConfront][GrossPrimaryProductivity/FLUXCOM][4x5_out_of_the_box_ann]
ValueError: Error from parse_expr with transformed code: 'FATES_FRACTION *FATES_GPP '

The above exception was the direct cause of the following exception:

Traceback (most recent call last):
  File "/glade/u/home/rfisher/.local/bin/ilamb-run", line 561, in WorkConfront
    c.confront(m)
  File "/glade/u/home/rfisher/.local/lib/python3.9/site-packages/ILAMB/Confrontation.py", line 431, in confront
    obs, mod = self.stageData(m)
  File "/glade/u/home/rfisher/.local/lib/python3.9/site-packages/ILAMB/Confrontation.py", line 369, in stageData
    mod = m.extractTimeSeries(
  File "/glade/u/home/rfisher/.local/lib/python3.9/site-packages/ILAMB/ModelResult.py", line 413, in extractTimeSeries
    v = self.derivedVariable(
  File "/glade/u/home/rfisher/.local/lib/python3.9/site-packages/ILAMB/ModelResult.py", line 553, in derivedVariable
    result, unit = il.SympifyWithArgsUnits(expression, args, units)
  File "/glade/u/home/rfisher/.local/lib/python3.9/site-packages/ILAMB/ilamblib.py", line 632, in SympifyWithArgsUnits
    return sympify(str(expression), locals=args), units[ekey]
  File "/glade/u/home/rfisher/.local/lib/python3.9/site-packages/sympy/core/sympify.py", line 495, in sympify
    expr = parse_expr(a, local_dict=locals, transformations=transformations, evaluate=evaluate)
  File "/glade/u/home/rfisher/.local/lib/python3.9/site-packages/sympy/parsing/sympy_parser.py", line 1087, in parse_expr
    raise e from ValueError(f"Error from parse_expr with transformed code: {code!r}")
  File "/glade/u/home/rfisher/.local/lib/python3.9/site-packages/sympy/parsing/sympy_parser.py", line 1078, in parse_expr
    rv = eval_expr(code, local_dict, global_dict)
  File "/glade/u/home/rfisher/.local/lib/python3.9/site-packages/sympy/parsing/sympy_parser.py", line 906, in eval_expr
    expr = eval(
  File "<string>", line 1, in <module>
FloatingPointError: overflow encountered in multiply

[DEBUG][0][extractTimeSeries][4x5_out_of_the_box_ann] Could not find [FATES_GPP] in the model results
[DEBUG][0][WorkConfront][GrossPrimaryProductivity/WECANN][4x5_out_of_the_box_ann]
Traceback (most recent call last):
  File "/glade/u/home/rfisher/.local/bin/ilamb-run", line 561, in WorkConfront
    c.confront(m)
  File "/glade/u/home/rfisher/.local/lib/python3.9/site-packages/ILAMB/Confrontation.py", line 431, in confront
    obs, mod = self.stageData(m)
  File "/glade/u/home/rfisher/.local/lib/python3.9/site-packages/ILAMB/Confrontation.py", line 369, in stageData
    mod = m.extractTimeSeries(
  File "/glade/u/home/rfisher/.local/lib/python3.9/site-packages/ILAMB/ModelResult.py", line 413, in extractTimeSeries
    v = self.derivedVariable(
  File "/glade/u/home/rfisher/.local/lib/python3.9/site-packages/ILAMB/ModelResult.py", line 499, in derivedVariable
    Vs[arg] = self.extractTimeSeries(
  File "/glade/u/home/rfisher/.local/lib/python3.9/site-packages/ILAMB/ModelResult.py", line 437, in extractTimeSeries
    raise il.VarNotInModel()
ILAMB.ilamblib.VarNotInModel: VarNotInModel

[DEBUG][0][extractTimeSeries][4x5_out_of_the_box_ann] Could not find [FATES_NEP] in the model results
[DEBUG][0][WorkConfront][NetEcosystemExchange/FLUXNET2015][4x5_out_of_the_box_ann]
Traceback (most recent call last):
  File "/glade/u/home/rfisher/.local/bin/ilamb-run", line 561, in WorkConfront
    c.confront(m)
  File "/glade/u/home/rfisher/.local/lib/python3.9/site-packages/ILAMB/Confrontation.py", line 431, in confront
    obs, mod = self.stageData(m)
  File "/glade/u/home/rfisher/.local/lib/python3.9/site-packages/ILAMB/Confrontation.py", line 369, in stageData
    mod = m.extractTimeSeries(
  File "/glade/u/home/rfisher/.local/lib/python3.9/site-packages/ILAMB/ModelResult.py", line 413, in extractTimeSeries
    v = self.derivedVariable(
  File "/glade/u/home/rfisher/.local/lib/python3.9/site-packages/ILAMB/ModelResult.py", line 499, in derivedVariable
    Vs[arg] = self.extractTimeSeries(
  File "/glade/u/home/rfisher/.local/lib/python3.9/site-packages/ILAMB/ModelResult.py", line 437, in extractTimeSeries
    raise il.VarNotInModel()
ILAMB.ilamblib.VarNotInModel: VarNotInModel

[DEBUG][0][extractTimeSeries][4x5_out_of_the_box_ann] Could not find [HR] in the model results
[DEBUG][0][WorkConfront][EcosystemRespiration/FLUXNET2015][4x5_out_of_the_box_ann]
Traceback (most recent call last):
  File "/glade/u/home/rfisher/.local/bin/ilamb-run", line 561, in WorkConfront
    c.confront(m)
  File "/glade/u/home/rfisher/.local/lib/python3.9/site-packages/ILAMB/Confrontation.py", line 431, in confront
    obs, mod = self.stageData(m)
  File "/glade/u/home/rfisher/.local/lib/python3.9/site-packages/ILAMB/Confrontation.py", line 369, in stageData
    mod = m.extractTimeSeries(
  File "/glade/u/home/rfisher/.local/lib/python3.9/site-packages/ILAMB/ModelResult.py", line 413, in extractTimeSeries
    v = self.derivedVariable(
  File "/glade/u/home/rfisher/.local/lib/python3.9/site-packages/ILAMB/ModelResult.py", line 499, in derivedVariable
    Vs[arg] = self.extractTimeSeries(
  File "/glade/u/home/rfisher/.local/lib/python3.9/site-packages/ILAMB/ModelResult.py", line 437, in extractTimeSeries
    raise il.VarNotInModel()
ILAMB.ilamblib.VarNotInModel: VarNotInModel

[DEBUG][0][extractTimeSeries][4x5_out_of_the_box_ann] Could not find [HR] in the model results
[DEBUG][0][WorkConfront][EcosystemRespiration/FLUXCOM][4x5_out_of_the_box_ann]
Traceback (most recent call last):
  File "/glade/u/home/rfisher/.local/bin/ilamb-run", line 561, in WorkConfront
    c.confront(m)
  File "/glade/u/home/rfisher/.local/lib/python3.9/site-packages/ILAMB/Confrontation.py", line 431, in confront
    obs, mod = self.stageData(m)
  File "/glade/u/home/rfisher/.local/lib/python3.9/site-packages/ILAMB/Confrontation.py", line 369, in stageData
    mod = m.extractTimeSeries(
  File "/glade/u/home/rfisher/.local/lib/python3.9/site-packages/ILAMB/ModelResult.py", line 413, in extractTimeSeries
    v = self.derivedVariable(
  File "/glade/u/home/rfisher/.local/lib/python3.9/site-packages/ILAMB/ModelResult.py", line 499, in derivedVariable
    Vs[arg] = self.extractTimeSeries(
  File "/glade/u/home/rfisher/.local/lib/python3.9/site-packages/ILAMB/ModelResult.py", line 437, in extractTimeSeries
    raise il.VarNotInModel()
ILAMB.ilamblib.VarNotInModel: VarNotInModel

[DEBUG][0][extractTimeSeries][4x5_out_of_the_box_ann] Could not find [QSOIL] in the model results
[DEBUG][0][WorkConfront][Evapotranspiration/GLEAMv3.3a][4x5_out_of_the_box_ann]
Traceback (most recent call last):
  File "/glade/u/home/rfisher/.local/bin/ilamb-run", line 561, in WorkConfront
    c.confront(m)
  File "/glade/u/home/rfisher/.local/lib/python3.9/site-packages/ILAMB/Confrontation.py", line 431, in confront
    obs, mod = self.stageData(m)
  File "/glade/u/home/rfisher/.local/lib/python3.9/site-packages/ILAMB/Confrontation.py", line 369, in stageData
    mod = m.extractTimeSeries(
  File "/glade/u/home/rfisher/.local/lib/python3.9/site-packages/ILAMB/ModelResult.py", line 413, in extractTimeSeries
    v = self.derivedVariable(
  File "/glade/u/home/rfisher/.local/lib/python3.9/site-packages/ILAMB/ModelResult.py", line 499, in derivedVariable
    Vs[arg] = self.extractTimeSeries(
  File "/glade/u/home/rfisher/.local/lib/python3.9/site-packages/ILAMB/ModelResult.py", line 437, in extractTimeSeries
    raise il.VarNotInModel()
ILAMB.ilamblib.VarNotInModel: VarNotInModel

[DEBUG][0][extractTimeSeries][4x5_out_of_the_box_ann] Could not find [QSOIL] in the model results
[DEBUG][0][WorkConfront][Evapotranspiration/MODIS][4x5_out_of_the_box_ann]
Traceback (most recent call last):
  File "/glade/u/home/rfisher/.local/bin/ilamb-run", line 561, in WorkConfront
    c.confront(m)
  File "/glade/u/home/rfisher/.local/lib/python3.9/site-packages/ILAMB/Confrontation.py", line 431, in confront
    obs, mod = self.stageData(m)
  File "/glade/u/home/rfisher/.local/lib/python3.9/site-packages/ILAMB/Confrontation.py", line 369, in stageData
    mod = m.extractTimeSeries(
  File "/glade/u/home/rfisher/.local/lib/python3.9/site-packages/ILAMB/ModelResult.py", line 413, in extractTimeSeries
    v = self.derivedVariable(
  File "/glade/u/home/rfisher/.local/lib/python3.9/site-packages/ILAMB/ModelResult.py", line 499, in derivedVariable
    Vs[arg] = self.extractTimeSeries(
  File "/glade/u/home/rfisher/.local/lib/python3.9/site-packages/ILAMB/ModelResult.py", line 437, in extractTimeSeries
    raise il.VarNotInModel()
ILAMB.ilamblib.VarNotInModel: VarNotInModel

[DEBUG][0][extractTimeSeries][4x5_out_of_the_box_ann] Could not find [QSOIL] in the model results
[DEBUG][0][WorkConfront][Evapotranspiration/MOD16A2][4x5_out_of_the_box_ann]
Traceback (most recent call last):
  File "/glade/u/home/rfisher/.local/bin/ilamb-run", line 561, in WorkConfront
    c.confront(m)
  File "/glade/u/home/rfisher/.local/lib/python3.9/site-packages/ILAMB/Confrontation.py", line 431, in confront
    obs, mod = self.stageData(m)
  File "/glade/u/home/rfisher/.local/lib/python3.9/site-packages/ILAMB/Confrontation.py", line 369, in stageData
    mod = m.extractTimeSeries(
  File "/glade/u/home/rfisher/.local/lib/python3.9/site-packages/ILAMB/ModelResult.py", line 413, in extractTimeSeries
    v = self.derivedVariable(
  File "/glade/u/home/rfisher/.local/lib/python3.9/site-packages/ILAMB/ModelResult.py", line 499, in derivedVariable
    Vs[arg] = self.extractTimeSeries(
  File "/glade/u/home/rfisher/.local/lib/python3.9/site-packages/ILAMB/ModelResult.py", line 437, in extractTimeSeries
    raise il.VarNotInModel()
ILAMB.ilamblib.VarNotInModel: VarNotInModel

[INFO][0][AnalysisMeanStateSites][hfls] Bias scored using Collier2018
[INFO][0][AnalysisMeanStateSites][hfls] RMSE scored using Collier2018
[INFO][0][confront][LatentHeat/FLUXNET2015][4x5_out_of_the_box_ann] Success
[INFO][0][MakeComparable][LatentHeat/FLUXCOM][4x5_out_of_the_box_ann] Spatial data was clipped from the reference:  before: [420 360 720] after: [420 360 711]
[INFO][0][AnalysisMeanStateSpace][hfls] Bias scored using Collier2018
[INFO][0][confront][LatentHeat/FLUXCOM][4x5_out_of_the_box_ann] Success
[INFO][0][MakeComparable][LatentHeat/DOLCE][4x5_out_of_the_box_ann] Spatial data was clipped from the reference:  before: [120 360 720] after: [120 360 711]
[INFO][0][AnalysisMeanStateSpace][hfls] Bias scored using Collier2018
[INFO][0][confront][LatentHeat/DOLCE][4x5_out_of_the_box_ann] Success
[INFO][0][MakeComparable][LatentHeat/CLASS][4x5_out_of_the_box_ann] Spatial data was clipped from the reference:  before: [ 84 360 720] after: [ 84 360 711]
[DEBUG][0][WorkConfront][LatentHeat/CLASS][4x5_out_of_the_box_ann]
Traceback (most recent call last):
  File "/glade/u/home/rfisher/.local/bin/ilamb-run", line 561, in WorkConfront
    c.confront(m)
  File "/glade/u/home/rfisher/.local/lib/python3.9/site-packages/ILAMB/Confrontation.py", line 462, in confront
    il.AnalysisMeanStateSpace(
  File "/glade/u/home/rfisher/.local/lib/python3.9/site-packages/ILAMB/ilamblib.py", line 1754, in AnalysisMeanStateSpace
    REF = ref.interpolate(lat=lat, lon=lon, lat_bnds=lat_bnds, lon_bnds=lon_bnds)
  File "/glade/u/home/rfisher/.local/lib/python3.9/site-packages/ILAMB/Variable.py", line 1546, in interpolate
    data_bnds = self.data_bnds[ind]
  File "/glade/u/apps/opt/conda/envs/npl-2023a/lib/python3.9/site-packages/numpy/ma/core.py", line 3222, in __getitem__
    dout = self.data[indx]
IndexError: too many indices for array: array is 3-dimensional, but 4 were indexed

[DEBUG][0][extractTimeSeries][4x5_out_of_the_box_ann] Could not find [hfls,le,EFLX_LH_TOT] in the model results
[DEBUG][0][WorkConfront][LatentHeat/WECANN][4x5_out_of_the_box_ann]
Traceback (most recent call last):
  File "/glade/u/home/rfisher/.local/bin/ilamb-run", line 561, in WorkConfront
    c.confront(m)
  File "/glade/u/home/rfisher/.local/lib/python3.9/site-packages/ILAMB/Confrontation.py", line 431, in confront
    obs, mod = self.stageData(m)
  File "/glade/u/home/rfisher/.local/lib/python3.9/site-packages/ILAMB/Confrontation.py", line 369, in stageData
    mod = m.extractTimeSeries(
  File "/glade/u/home/rfisher/.local/lib/python3.9/site-packages/ILAMB/ModelResult.py", line 437, in extractTimeSeries
    raise il.VarNotInModel()
ILAMB.ilamblib.VarNotInModel: VarNotInModel

[INFO][0][AnalysisMeanStateSites][hfss] Bias scored using Collier2018
[INFO][0][AnalysisMeanStateSites][hfss] RMSE scored using Collier2018
[INFO][0][confront][SensibleHeat/FLUXNET2015][4x5_out_of_the_box_ann] Success
[INFO][0][MakeComparable][SensibleHeat/FLUXCOM][4x5_out_of_the_box_ann] Spatial data was clipped from the reference:  before: [420 360 720] after: [420 360 711]
[INFO][0][AnalysisMeanStateSpace][hfss] Bias scored using Collier2018
[INFO][0][confront][SensibleHeat/FLUXCOM][4x5_out_of_the_box_ann] Success
[INFO][0][MakeComparable][SensibleHeat/CLASS][4x5_out_of_the_box_ann] Spatial data was clipped from the reference:  before: [ 84 360 720] after: [ 84 360 711]
[DEBUG][0][WorkConfront][SensibleHeat/CLASS][4x5_out_of_the_box_ann]
Traceback (most recent call last):
  File "/glade/u/home/rfisher/.local/bin/ilamb-run", line 561, in WorkConfront
    c.confront(m)
  File "/glade/u/home/rfisher/.local/lib/python3.9/site-packages/ILAMB/Confrontation.py", line 462, in confront
    il.AnalysisMeanStateSpace(
  File "/glade/u/home/rfisher/.local/lib/python3.9/site-packages/ILAMB/ilamblib.py", line 1754, in AnalysisMeanStateSpace
    REF = ref.interpolate(lat=lat, lon=lon, lat_bnds=lat_bnds, lon_bnds=lon_bnds)
  File "/glade/u/home/rfisher/.local/lib/python3.9/site-packages/ILAMB/Variable.py", line 1546, in interpolate
    data_bnds = self.data_bnds[ind]
  File "/glade/u/apps/opt/conda/envs/npl-2023a/lib/python3.9/site-packages/numpy/ma/core.py", line 3222, in __getitem__
    dout = self.data[indx]
IndexError: too many indices for array: array is 3-dimensional, but 4 were indexed

[DEBUG][0][extractTimeSeries][4x5_out_of_the_box_ann] Could not find [hfss,sh,FSH] in the model results
[DEBUG][0][WorkConfront][SensibleHeat/WECANN][4x5_out_of_the_box_ann]
Traceback (most recent call last):
  File "/glade/u/home/rfisher/.local/bin/ilamb-run", line 561, in WorkConfront
    c.confront(m)
  File "/glade/u/home/rfisher/.local/lib/python3.9/site-packages/ILAMB/Confrontation.py", line 431, in confront
    obs, mod = self.stageData(m)
  File "/glade/u/home/rfisher/.local/lib/python3.9/site-packages/ILAMB/Confrontation.py", line 369, in stageData
    mod = m.extractTimeSeries(
  File "/glade/u/home/rfisher/.local/lib/python3.9/site-packages/ILAMB/ModelResult.py", line 437, in extractTimeSeries
    raise il.VarNotInModel()
ILAMB.ilamblib.VarNotInModel: VarNotInModel

[DEBUG][0][WorkConfront][Albedo/GEWEX.SRB][4x5_out_of_the_box_ann]
Traceback (most recent call last):
  File "/glade/u/home/rfisher/.local/bin/ilamb-run", line 561, in WorkConfront
    c.confront(m)
  File "/glade/u/home/rfisher/.local/lib/python3.9/site-packages/ILAMB/ConfAlbedo.py", line 157, in confront
    obs, mod, obs_timeint, mod_timeint = self.stageData(m)
  File "/glade/u/home/rfisher/.local/lib/python3.9/site-packages/ILAMB/ConfAlbedo.py", line 44, in stageData
    dn_obs = Variable(
  File "/glade/u/home/rfisher/.local/lib/python3.9/site-packages/ILAMB/Variable.py", line 140, in __init__
    out = il.FromNetCDF4(
  File "/glade/u/home/rfisher/.local/lib/python3.9/site-packages/ILAMB/ilamblib.py", line 724, in FromNetCDF4
    dset = Dataset(filename, mode="r")
  File "src/netCDF4/_netCDF4.pyx", line 2463, in netCDF4._netCDF4.Dataset.__init__
  File "src/netCDF4/_netCDF4.pyx", line 2026, in netCDF4._netCDF4._ensure_nc_success
FileNotFoundError: [Errno 2] No such file or directory: b'/glade/work/rfisher/FATES_calibration/ILAMB_data/DATA/rsds/GEWEX.SRB/rsds_0.5x0.5.nc'

[INFO][0][AnalysisMeanStateSites][rsns] Bias scored using Collier2018
[INFO][0][AnalysisMeanStateSites][rsns] RMSE scored using Collier2018
[INFO][0][confront][SurfaceNetSWRadiation/FLUXNET2015][4x5_out_of_the_box_ann] Success
[INFO][0][AnalysisMeanStateSites][rlus] Bias scored using Collier2018
[INFO][0][AnalysisMeanStateSites][rlus] RMSE scored using Collier2018
[INFO][0][confront][SurfaceUpwardLWRadiation/FLUXNET2015][4x5_out_of_the_box_ann] Success
[INFO][0][AnalysisMeanStateSites][rlns] Bias scored using Collier2018
[INFO][0][AnalysisMeanStateSites][rlns] RMSE scored using Collier2018
[INFO][0][confront][SurfaceNetLWRadiation/FLUXNET2015][4x5_out_of_the_box_ann] Success
[INFO][0][AnalysisMeanStateSites][rns] Bias scored using Collier2018
[INFO][0][AnalysisMeanStateSites][rns] RMSE scored using Collier2018
[INFO][0][confront][SurfaceNetRadiation/FLUXNET2015][4x5_out_of_the_box_ann] Success
[INFO][0][MakeComparable][SurfaceNetRadiation/CLASS][4x5_out_of_the_box_ann] Spatial data was clipped from the reference:  before: [ 84 360 720] after: [ 84 360 711]
[DEBUG][0][WorkConfront][SurfaceNetRadiation/CLASS][4x5_out_of_the_box_ann]
Traceback (most recent call last):
  File "/glade/u/home/rfisher/.local/bin/ilamb-run", line 561, in WorkConfront
    c.confront(m)
  File "/glade/u/home/rfisher/.local/lib/python3.9/site-packages/ILAMB/Confrontation.py", line 462, in confront
    il.AnalysisMeanStateSpace(
  File "/glade/u/home/rfisher/.local/lib/python3.9/site-packages/ILAMB/ilamblib.py", line 1754, in AnalysisMeanStateSpace
    REF = ref.interpolate(lat=lat, lon=lon, lat_bnds=lat_bnds, lon_bnds=lon_bnds)
  File "/glade/u/home/rfisher/.local/lib/python3.9/site-packages/ILAMB/Variable.py", line 1546, in interpolate
    data_bnds = self.data_bnds[ind]
  File "/glade/u/apps/opt/conda/envs/npl-2023a/lib/python3.9/site-packages/numpy/ma/core.py", line 3222, in __getitem__
    dout = self.data[indx]
IndexError: too many indices for array: array is 3-dimensional, but 4 were indexed

[DEBUG][0][extractTimeSeries][4x5_out_of_the_box_ann] Could not find [hfdsl,FGR12] in the model results
[DEBUG][0][WorkConfront][GroundHeatFlux/CLASS][4x5_out_of_the_box_ann]
Traceback (most recent call last):
  File "/glade/u/home/rfisher/.local/bin/ilamb-run", line 561, in WorkConfront
    c.confront(m)
  File "/glade/u/home/rfisher/.local/lib/python3.9/site-packages/ILAMB/Confrontation.py", line 431, in confront
    obs, mod = self.stageData(m)
  File "/glade/u/home/rfisher/.local/lib/python3.9/site-packages/ILAMB/Confrontation.py", line 369, in stageData
    mod = m.extractTimeSeries(
  File "/glade/u/home/rfisher/.local/lib/python3.9/site-packages/ILAMB/ModelResult.py", line 437, in extractTimeSeries
    raise il.VarNotInModel()
ILAMB.ilamblib.VarNotInModel: VarNotInModel

[INFO][0][modelPlots][Biomass/NBCD2000][4x5_out_of_the_box_ann] Success
[INFO][0][modelPlots][LatentHeat/FLUXNET2015][4x5_out_of_the_box_ann] Success
[INFO][0][modelPlots][LatentHeat/FLUXCOM][4x5_out_of_the_box_ann] Success
[INFO][0][modelPlots][LatentHeat/DOLCE][4x5_out_of_the_box_ann] Success
[INFO][0][modelPlots][SensibleHeat/FLUXNET2015][4x5_out_of_the_box_ann] Success
[INFO][0][modelPlots][SensibleHeat/FLUXCOM][4x5_out_of_the_box_ann] Success
[INFO][0][modelPlots][SurfaceNetSWRadiation/FLUXNET2015][4x5_out_of_the_box_ann] Success
[INFO][0][modelPlots][SurfaceNetSWRadiation/GEWEX.SRB][4x5_out_of_the_box_ann] Success
[INFO][0][modelPlots][SurfaceNetSWRadiation/WRMC.BSRN][4x5_out_of_the_box_ann] Success
[INFO][0][modelPlots][SurfaceUpwardLWRadiation/FLUXNET2015][4x5_out_of_the_box_ann] Success
[INFO][0][modelPlots][SurfaceUpwardLWRadiation/GEWEX.SRB][4x5_out_of_the_box_ann] Success
[INFO][0][modelPlots][SurfaceUpwardLWRadiation/WRMC.BSRN][4x5_out_of_the_box_ann] Success
[INFO][0][modelPlots][SurfaceNetLWRadiation/FLUXNET2015][4x5_out_of_the_box_ann] Success
[INFO][0][modelPlots][SurfaceNetLWRadiation/GEWEX.SRB][4x5_out_of_the_box_ann] Success
[INFO][0][modelPlots][SurfaceNetLWRadiation/WRMC.BSRN][4x5_out_of_the_box_ann] Success
[INFO][0][modelPlots][SurfaceNetRadiation/FLUXNET2015][4x5_out_of_the_box_ann] Success
[INFO][0][modelPlots][SurfaceNetRadiation/GEWEX.SRB][4x5_out_of_the_box_ann] Success
[INFO][0][modelPlots][SurfaceNetRadiation/WRMC.BSRN][4x5_out_of_the_box_ann] Success
[INFO][0][<module>][total time] 83.3 s
